<?xml version="1.0"?>
<robot name="fanuc"  xmlns:xacro="http://ros.org/wiki/xacro">
    
    
    <!-- <link name="world"/> -->


<joint name="world_joint_2" type="fixed">
    <parent link="world" />
    <child link = "base_blob" />
    <origin xyz="2.20 0" rpy="0.0 0.0 0" />
</joint>

    
    
    
    
    
    <link name="base_blob">
      <inertial>
        <mass value="1.584994"/>
        <origin xyz="0.0 0.0 0.0" rpy="0 0 0" />
        <inertia
          ixx="0.01042" ixy="0.001177" ixz="-0.0008871"
          iyy="0.01045" iyz="0.0002226"
          izz="0.01817"/>
      </inertial>
      <visual>
        <geometry>
          <mesh filename="package://fanuc_gazebo/mesh/base_table.stl" scale="1 1 0.6"/>
        </geometry>
        <material name="RED">
          <color rgba="1.0 0.0 0.0 1.0"/>
        </material>
      </visual>
      <collision>
        <geometry>
          <mesh filename="package://fanuc_gazebo/mesh/base_table.stl" scale="1 1 0.6" />
        </geometry>
      </collision>
</link>


<joint name="main_joint" type="revolute">
      <parent link="base_blob" />
      <child link = "rot_blob" />
      <origin xyz="0 0 0.62" rpy="0.0 0.0 0.0" />
      <axis xyz="0 0 1" />
      <limit lower="-3.142" upper="3.142" effort="150.0" velocity="1.5"/>
</joint>




    <link name="rot_blob">
      <inertial>
        <mass value="1.584994"/>
        <origin xyz="0.0 0.0 0.0" rpy="0 0 0" />
        <inertia
          ixx="0.01042" ixy="0.001177" ixz="-0.0008871"
          iyy="0.01045" iyz="0.0002226"
          izz="0.01817"/>
      </inertial>
      <visual>
        <geometry>
          <mesh filename="package://fanuc_gazebo/mesh/rot_block.stl" scale="1 1 0.6"/>
        </geometry>
        <material name="RED">
          <color rgba="1.0 0.0 0.0 1.0"/>
        </material>
      </visual>
      <collision>
        <geometry>
          <mesh filename="package://fanuc_gazebo/mesh/rot_block.stl" scale="1 1 0.6" />
        </geometry>
      </collision>
</link>





<!-- <transmission name="main_joint_tran">
    <type>transmission_interface/SimpleTransmission</type>
    <joint name="main_joint">
      <hardwareInterface>hardware_interface/EffortJointInterface</hardwareInterface>
    </joint>
    <actuator name="main_joint_motor">
      <hardwareInterface>hardware_interface/EffortJointInterface</hardwareInterface>
      <mechanicalReduction>1</mechanicalReduction>
    </actuator>
</transmission> -->

<!-- 

<gazebo>
      <plugin name="gazebo_ros_control" filename="libgazebo_ros_control.so">
         <robotSimType>gazebo_ros_control/DefaultRobotHWSim</robotSimType>
      </plugin>
   </gazebo> -->



</robot>